Workbook

Sheet CALCULADORA COSTES
A1: Calculadora | B1: PRECIO (€/KG) | C1: CONSUMO (KG/KM) | D1: €/KM (ENERGIA) | E1: COSTE RENTING | F1: €/KM (ud. TRAILER) | G1: €/DIA (trailer) | H1: Extracoste | I1: TARIFA | K1: KG C02/KM | L1: % - CO2 | M1: COSTE EMISIÓN CO2 | R1: vs DUO D
A2: DIESEL | B2: 1 | C2: 0.28 | D2: =B2*C2 -> 0.28 | E2: 2000 | F2: ='GASOIL '!E48+E27*K2 -> 1.4076342 | G2: =F2*$B$14 -> 422.29025 | H2: =F2/$F$2-1 -> 0 | I2: =G2*(1+$B$18) -> 506.74831 | K2: =C2*P2 -> 0.69804 | L2: =($K$2-K2)/$K$2 -> 0 | M2: =$E$27*K2 -> 0 | O2: FE DIESEL | P2: 2.493 | R2: =F2/$F$9-1 -> 0.55787007
A3: GAS NATURAL | B3: 1.7 | C3: =E15/100 -> 0.264 | D3: =B3*C3 -> 0.4488 | E3: 2400 | F3: ='GAS NATURAL'!E47+E27/1000*K3 -> 1.6967605 | G3: =F3*$B$14 -> 509.02815 | H3: =F3/$F$2-1 -> 0.20539875 | I3: =G3*(1+$B$18) -> 610.83377 | K3: =P3*C3 -> 0.718344 | L3: =($K$2-K3)/$K$2 -> -0.029087158 | M3: =$E$27*K3 -> 0 | O3: FE LNG | P3: 2.721 | R3: =F3/$F$9-1 -> 0.87785464
A4: H2 | B4: 7 | C4: =E16/100 -> 0.09 | D4: =B4*C4 -> 0.63 | E4: 6200 | F4: ='H2'!E47+E27/1000*K4 -> 2.4839964 | G4: =F4*$B$14 -> 745.19891 | H4: =F4/$F$2-1 -> 0.76466045 | I4: =G4*(1+$B$18) -> 894.23869 | K4: 0 | L4: =($K$2-K4)/$K$2 -> 1 | M4: =$E$27*K4 -> 0 | R4: =F4/$F$9-1 -> 1.7491117
A5: BIOMETANO | B5: 1.8 | C5: =C3 -> 0.264 | D5: =B5*C5 -> 0.4752 | E5: =E3 -> 2400 | F5: =BIOMETANO!E47+E27/1000*K5 -> 1.7242694 | G5: =F5*$B$14 -> 517.28083 | H5: =F5/$F$2-1 -> 0.22494143 | I5: =G5*(1+$B$18) -> 620.73699 | K5: =C5*P3*(1-P9*P5)+C3*(1-P9) -> 0.0718344 | L5: =($K$2-K5)/$K$2 -> 0.89709128 | M5: =$E$27*K5 -> 0 | O5: % REDUCCIÓN BIO | P5: 0.9 | R5: =F5/$F$9-1 -> 0.9082996
A6: ELECTRICO | B6: 0.23 | C6: =E18/100 -> 1.83 | D6: =B6*C6 -> 0.4209 | E6: 4000 | F6: =ELÉCTRICO!G45+E27/1000*K6 -> 1.9192354 | G6: =F6*$B$14 -> 575.77062 | H6: =F6/$F$2-1 -> 0.36344756 | I6: =G6*(1+$B$18) -> 690.92474 | K6: 0 | L6: =($K$2-K6)/$K$2 -> 1 | M6: =$E$27*K6 -> 0 | O6: % REDUCCION HVO | P6: 0.9 | R6: =F6/$F$9-1 -> 1.1240742
A7: HVO | B7: 1.35 | C7: =C2 -> 0.28 | D7: =B7*C7 -> 0.378 | E7: =E2 -> 2000 | F7: =HVO!E48+E27/1000*K7 -> 1.5095542 | G7: =F7*$B$14 -> 452.86625 | H7: =F7/$F$2-1 -> 0.072405176 | I7: =G7*(1+$B$18) -> 543.43951 | K7: =C7*P2*P8*(1-P6)+C2*P2*(1-P8) -> 0.069804 | L7: =($K$2-K7)/$K$2 -> 0.9 | M7: =$E$27*K7 -> 0 | R7: =F7/$F$9-1 -> 0.67066793
A8: DUO H2 | B8: =B4 -> 7 | C8: =C4*2*(1-E20) -> 0.126 | D8: =B8*C8 -> 0.882 | E8: =E4 -> 6200 | F8: ='DUOTRAILER H2'!E48/2+E27*K8 -> 1.4735148 | G8: =F8*$B$14 -> 442.05444 | H8: =F8/$F$2-1 -> 0.046802363 | I8: =G8*(1+$B$18) -> 530.46532 | K8: 0 | L8: =($K$2-K8)/$K$2 -> 1 | M8: =$E$27*K8 -> 0 | O8: % HVO | P8: 1 | R8: =F8/$F$9-1 -> 0.63078207
A9: DUO GASOIL | B9: =B2 -> 1 | C9: =C2*2*(1-E20) -> 0.392 | D9: =B9*C9 -> 0.392 | E9: 2200 | F9: ='DUOTRAILER GASOIL'!E48/2+E27/1000*K9 -> 0.90356327 | G9: =F9*$B$14 -> 271.06898 | H9: =F9/$F$2-1 -> -0.35809795 | I9: =G9*(1+$B$18) -> 325.28278 | K9: =C9*P2/2 -> 0.488628 | L9: =($K$2-K9)/$K$2 -> 0.3 | M9: =$E$27*K9 -> 0 | O9: % Biometano | P9: 1 | R9: =F9/$F$9-1 -> 0
A10: DUO BIOMETANO | B10: =B5 -> 1.8 | C10: =C5*2*(1-E20) -> 0.3696 | D10: =B10*C10 -> 0.66528 | E10: =E5 -> 2400 | F10: ='DUOTRAILER BIOMETANO'!E48/2+E27/1000*K10 -> 1.0614264 | G10: =F10*$B$14 -> 318.42793 | H10: =F10/$F$2-1 -> -0.24595008 | I10: =G10*(1+$B$18) -> 382.11352 | K10: =K5*0.7 -> 0.05028408 | L10: =($K$2-K10)/$K$2 -> 0.9279639 | M10: =$E$27*K10 -> 0 | O10: % H2 VERDE | P10: 1 | R10: =F10/$F$9-1 -> 0.17471181
A11: DUO HVO | B11: =B7 -> 1.35 | C11: 0.41 | D11: =B11*C11 -> 0.5535 | E11: =E9 -> 2200 | F11: ='DUOTRAILER HVO'!E48/2+E27/1000*K11 -> 0.98754327 | G11: =F11*$B$14 -> 296.26298 | H11: =F11/$F$2-1 -> -0.29843756 | I11: =G11*(1+$B$18) -> 355.51558 | K11: =C11*0.174 -> 0.07134 | L11: =($K$2-K11)/$K$2 -> 0.89779955 | M11: =$E$27*K11 -> 0 | R11: =F11/$F$9-1 -> 0.092943131
A12: DUO ELECTRICO | B12: =B6 -> 0.23 | C12: =C6*(1-E20) -> 1.281 | D12: =B12*C12 -> 0.29463 | E12: =E6 -> 4000 | F12: ='DUOTRAILER ELECTRICO'!E48/2+E27/1000*K12 -> 0.99474905 | G12: =B14*F12 -> 298.42472 | H12: =F12/$F$2-1 -> -0.29331849 | I12: =G12*(1+$B$18) -> 358.10966 | K12: =K6 -> 0 | L12: =L6 -> 1 | M12: =M6 -> 0 | R12: =F12/$F$9-1 -> 0.10091798
A14: KMS VEHICULO /DIA | B14: 300 | C14: (Modificable) | D14: Consumo Diesel /100 km | E14: 31
A15: DIAS MES | B15: 22 | C15: (Vinculado) | D15: Consumo GNL/100 km | E15: 26.4
A16: Conductores * | B16: {=_xlfn.IFS(B14<700,1,B14=700,1,B14>700,2)} -> 1 | C16: > 700 kms ---> 2 Cond | D16: Consumo H2/100 km | E16: 9
A17: SALARIO CONDUCTOR (Tabla R) | B17: 3048 | C17: < --Solo tabla roja | D17: Consumo BioGNC / 100 km | E17: 26.4
A18: MARGEN | B18: 0.2 | D18: Consumo KWH /100 km | E18: =183 -> 183
A19: Tipo de trailer | B19: Trailer | C19: Dolly | D19: Consumo HVO / 100 km | E19: =E14*1.02 -> 31.62
A20: PRECIO SEMIRREMOLQUE | B20: 450 | C20: 200 | D20: % Ahorro consumo Duo | E20: 0.3
A21: OPERATIVA CORREDOR | D21: TIPO H2 | E21: Verde | F21: Gris
A22: COSTE TRAILER YARD/ | B22: 50 | D22: PRECIO H2 | E22: 6 | F22: 1
A23: COSTE TRANSPORTE PLAZA | B23: 500 | D23: VEHICULO | E23: SIMPLE | F23: DUO
A24: Nº DESCARGAS PLAZA | B24: 10 | D24: KMS AUTOPISTA | E24: 0 | F24: 0
A25: KMS CORREDOR DUO | B25: 600 | D25: PRECIO AUTOPISTA | E25: 0.26 | F25: =E25*1.5 -> 0.39
A26: Nº ACARREOS VIAJE | B26: 1 | D26: EXTRA CONDUCTOR | E26: 0.05 | F26: (Vehículo especial)
A27: FACTOR CORRECTOR TARIFA | B27: 0.12 | D27: PRECIO t CO2 | E27: 0
A28: Se aplica corrector al coste dia simple Se considera que el duotrailer puede tener más productividad en corredor, No así el simple.
A29: DIESEL | B29: KMS | C29: COSTE ACARREO +YARD | D29: COSTE DUO DIESEL | E29: COSTE DUO+ ACARREO | F29: COSTE SIMPLE | G29: EXTRACOSTE | H29: DUO VS SIMPLE | I29: TARIFA NORMAL
A30: RUTA A | B30: =B25 -> 600 | C30: =(B23/B24+B22)*B26 -> 100 | D30: =B30*F9 -> 542.13796 | E30: =C30+D30 -> 642.13796 | F30: =B30*F2 -> 844.58051 | G30: =E30/I30-1 -> -0.32115712 | H30: =E30/F30-1 -> -0.23969597 | I30: =F2*B25*(1+B27) -> 945.93017
A31: HVO | B31: KMS | C31: COSTE ACARREO+YARD | D31: COSTE DUO HVO | E31: COSTE DUO+ ACARREO | F31: COSTE SIMPLE | G31: EXTRACOSTE | H31: DUO VS SIMPLE | I31: TARIFA NORMAL
A32: RUTA A | B32: =B25 -> 600 | C32: =(B23/B24+B22)*B26 -> 100 | D32: =F11*B32 -> 592.52596 | E32: =C32+D32 -> 692.52596 | F32: =F30 -> 844.58051 | G32: =E32/I32-1 -> -0.26788891 | H32: =E32/F32-1 -> -0.18003558 | I32: =F2*B25*(1+B27) -> 945.93017
A33: H2 | B33: KMS | C33: COSTE ACARREO +YARD | D33: COSTE DUO H2 | E33: COSTE DUO+ ACARREO | F33: COSTE SIMPLE | G33: EXTRACOSTE | H33: DUO VS SIMPLE | I33: TARIFA NORMAL
A34: RUTA A | B34: =B25 -> 600 | C34: =(B23/B24+B22)*B26 -> 100 | D34: =F8*B34 -> 884.10887 | E34: =C34+D34 -> 984.10887 | F34: =F30 -> 844.58051 | G34: =E34/I34-1 -> 0.040361016 | H34: =E34/F34-1 -> 0.16520434 | I34: =B25*F2*(1+B27) -> 945.93017
A35: Falta aplicar el margen
A36: DIFERENCIA | B36: 100 | C36: 200 | D36: 300 | E36: 400 | F36: 500 | G36: 600 | H36: 700 | I36: 800 | J36: 900 | K36: 1000 | L36: 1100 | M36: 1200
A37: GASOIL | B37: =B61/B61-1 -> 0 | C37: =C61/C61-1 -> 0 | D37: =D61/D61-1 -> 0 | E37: =E61/E61-1 -> 0 | F37: =F61/F61-1 -> 0 | G37: =G61/G61-1 -> 0 | H37: =H61/H61-1 -> 0 | I37: =I61/I61-1 -> 0 | ... M37: =M61/M61-1 -> 0
A38: HVO | B38: =B62/B61-1 -> 0.028321381 | C38: =C62/C61-1 -> 0.052109875 | D38: =D62/D61-1 -> 0.072373093 | E38: =E62/E61-1 -> 0.089840604 | F38: =F62/F61-1 -> 0.10505366 | G38: =G62/G61-1 -> 0.11842225 | H38: =H62/H61-1 -> 0.13026265 | I38: =I62/I61-1 -> 0.11276134 | ... M38: =M62/M61-1 -> 0.14417529
A39: H2 | B39: =B63/B61-1 -> 0.6753257 | C39: =C63/C61-1 -> 0.71433551 | D39: =D63/D61-1 -> 0.74756437 | E39: =E63/E61-1 -> 0.77620865 | F39: =F63/F61-1 -> 0.80115594 | G39: =G63/G61-1 -> 0.82307856 | H39: =H63/H61-1 -> 0.84249517 | I39: =I63/I61-1 -> 0.68847961 | ... M39: =M63/M61-1 -> 0.75849174
A40: ELÉCTRICO | B40: =B64/B61-1 -> 0.32537799 | C40: =C64/C61-1 -> 0.33679995 | D40: =D64/D61-1 -> 0.34652926 | E40: =E64/E61-1 -> 0.35491622 | F40: =F64/F61-1 -> 0.36222071 | G40: =G64/G61-1 -> 0.3686396 | H40: =H64/H61-1 -> 0.37432472 | I40: =I64/I61-1 -> 0.303794 | ... M40: =M64/M61-1 -> 0.32804781
A41: GAS NATURAL | B41: =B65/B61-1 -> 0.12378913 | C41: =C65/C61-1 -> 0.1587611 | D41: =D65/D61-1 -> 0.18855048 | E41: =E65/E61-1 -> 0.21422984 | F41: =F65/F61-1 -> 0.23659486 | G41: =G65/G61-1 -> 0.25624831 | H41: =H65/H61-1 -> 0.27365514 | I41: =I65/I61-1 -> 0.23155561 | ... M41: =M65/M61-1 -> 0.28015434
...

Sheet TABLAS 
A1: SIMPLE H2 / 4 € | N1: SIMPLE GNL | AA1: EXTRA COSTE
A2: KMS / % VERDE | B2: 0 | C2: 10 | D2: 20 | E2: 30 | F2: 40 | G2: 50 | H2: 60 | I2: 70 | J2: 80 | K2: 90 | L2: 100 | N2: KMS / % BIO | O2: 0 | P2: 10 | Q2: 20 | R2: 30 | S2: 40 | T2: 50 | U2: 60 | V2: 70 | W2: 80 | X2: 90 | Y2: 100 | AA2: KMS / % HVO | AB2: 0 | AC2: 10 | AD2: 20 | AE2: 30 | AF2: 40 | AG2: 50 | AH2: 60 | AI2: 70 | AJ2: 80 | AK2: 90 | AL2: 100
A3: 100 | B3: 0.77 | C3: 0.78 | D3: 0.78 | E3: 0.79 | F3: 0.8 | G3: 0.8 | H3: 0.81 | I3: 0.82 | J3: 0.82 | K3: 0.83 | L3: 0.84 | N3: 100 | O3: 0.15 | P3: 0.15 | Q3: 0.15 | R3: 0.16 | S3: 0.16 | T3: 0.17 | U3: 0.17 | V3: 0.17 | W3: 0.18 | X3: 0.18 | Y3: 0.19 | AA3: 100 | AB3: 0 | AC3: 0.01 | AD3: 0.03 | AE3: 0.04 | AF3: 0.05 | AG3: 0.06 | AH3: 0.08 | AI3: 0.09 | AJ3: 0.1 | AK3: 0.11 | AL3: 0.13
A4: 200 | B4: 0.67 | C4: 0.68 | D4: 0.69 | E4: 0.7 | F4: 0.71 | G4: 0.73 | H4: 0.74 | I4: 0.75 | J4: 0.76 | K4: 0.78 | L4: 0.79 | N4: 200 | O4: 0.11 | P4: 0.11 | Q4: 0.12 | R4: 0.13 | S4: 0.13 | T4: 0.14 | U4: 0.15 | V4: 0.16 | W4: 0.16 | X4: 0.17 | Y4: 0.18 | AA4: 200 | AB4: 0 | AC4: 0.02 | AD4: 0.05 | AE4: 0.07 | AF4: 0.09 | AG4: 0.12 | AH4: 0.14 | AI4: 0.16 | AJ4: 0.18 | AK4: 0.21 | AL4: 0.23
A5: 300 | B5: 0.58 | C5: 0.59 | D5: 0.61 | E5: 0.63 | F5: 0.64 | G5: 0.66 | H5: 0.68 | I5: 0.7 | J5: 0.71 | K5: 0.73 | L5: 0.75 | N5: 300 | O5: 0.07 | P5: 0.08 | Q5: 0.09 | R5: 0.1 | S5: 0.11 | T5: 0.12 | U5: 0.13 | V5: 0.14 | W5: 0.15 | X5: 0.16 | Y5: 0.17 | AA5: 300 | AB5: 0 | AC5: 0.03 | AD5: 0.06 | AE5: 0.1 | AF5: 0.13 | AG5: 0.16 | AH5: 0.19 | AI5: 0.22 | AJ5: 0.26 | AK5: 0.29 | AL5: 0.32
A6: 400 | B6: 0.5 | C6: 0.52 | D6: 0.54 | E6: 0.56 | F6: 0.59 | G6: 0.61 | H6: 0.63 | I6: 0.65 | J6: 0.67 | K6: 0.69 | L6: 0.71 | N6: 400 | O6: 0.04 | P6: 0.05 | Q6: 0.07 | R6: 0.08 | S6: 0.09 | T6: 0.1 | U6: 0.12 | V6: 0.13 | W6: 0.14 | X6: 0.15 | Y6: 0.17 | AA6: 400 | AB6: 0 | AC6: 0.04 | AD6: 0.08 | AE6: 0.12 | AF6: 0.16 | AG6: 0.2 | AH6: 0.24 | AI6: 0.28 | AJ6: 0.32 | AK6: 0.36 | AL6: 0.4
A7: 500 | B7: 0.44 | C7: 0.46 | D7: 0.48 | E7: 0.51 | F7: 0.53 | G7: 0.56 | H7: 0.58 | I7: 0.61 | J7: 0.63 | K7: 0.66 | L7: 0.68 | N7: 500 | O7: 0.02 | P7: 0.03 | Q7: 0.04 | R7: 0.06 | S7: 0.07 | T7: 0.09 | U7: 0.1 | V7: 0.12 | W7: 0.13 | X7: 0.15 | Y7: 0.16 | AA7: 500 | AB7: 0 | AC7: 0.05 | AD7: 0.09 | AE7: 0.14 | AF7: 0.18 | AG7: 0.23 | AH7: 0.28 | AI7: 0.32 | AJ7: 0.37 | AK7: 0.42 | AL7: 0.46
A8: 600 | B8: 0.38 | C8: 0.41 | D8: 0.43 | E8: 0.46 | F8: 0.49 | G8: 0.52 | H8: 0.54 | I8: 0.57 | J8: 0.6 | K8: 0.63 | L8: 0.65 | N8: 600 | O8: -0.01 | P8: 0.01 | Q8: 0.03 | R8: 0.04 | S8: 0.06 | T8: 0.07 | U8: 0.09 | V8: 0.11 | W8: 0.12 | X8: 0.14 | Y8: 0.16 | AA8: 600 | AB8: 0 | AC8: 0.05 | AD8: 0.1 | AE8: 0.16 | AF8: 0.21 | AG8: 0.26 | AH8: 0.31 | AI8: 0.36 | AJ8: 0.42 | AK8: 0.47 | AL8: 0.52
A9: 700 | B9: 0.33 | C9: 0.36 | D9: 0.39 | E9: 0.42 | F9: 0.45 | G9: 0.48 | H9: 0.51 | I9: 0.54 | J9: 0.57 | K9: 0.6 | L9: 0.63 | N9: 700 | O9: -0.03 | P9: -0.01 | Q9: 0.01 | R9: 0.03 | S9: 0.05 | T9: 0.06 | U9: 0.08 | V9: 0.1 | W9: 0.12 | X9: 0.13 | Y9: 0.15 | AA9: 700 | AB9: 0 | AC9: 0.06 | AD9: 0.11 | AE9: 0.17 | AF9: 0.23 | AG9: 0.29 | AH9: 0.34 | AI9: 0.4 | AJ9: 0.46 | AK9: 0.51 | AL9: 0.57
A10: 800 | B10: 0.24 | C10: 0.27 | D10: 0.29 | E10: 0.32 | F10: 0.34 | G10: 0.37 | H10: 0.39 | I10: 0.42 | J10: 0.45 | K10: 0.47 | L10: 0.5 | N10: 800 | O10: -0.01 | P10: 0 | Q10: 0.02 | R10: 0.03 | S10: 0.05 | T10: 0.06 | U10: 0.08 | V10: 0.09 | W10: 0.11 | X10: 0.12 | Y10: 0.14 | AA10: 800 | AB10: 0 | AC10: 0.05 | AD10: 0.1 | AE10: 0.14 | AF10: 0.19 | AG10: 0.24 | AH10: 0.29 | AI10: 0.34 | AJ10: 0.38 | AK10: 0.43 | AL10: 0.48
A11: 900 | B11: 0.21 | C11: 0.24 | D11: 0.27 | E11: 0.29 | F11: 0.32 | G11: 0.35 | H11: 0.38 | I11: 0.4 | J11: 0.43 | K11: 0.46 | L11: 0.49 | N11: 900 | O11: -0.03 | P11: -0.01 | Q11: 0.01 | R11: 0.02 | S11: 0.04 | T11: 0.06 | U11: 0.07 | V11: 0.09 | W11: 0.1 | X11: 0.12 | Y11: 0.14 | AA11: 900 | AB11: 0 | AC11: 0.05 | AD11: 0.1 | AE11: 0.16 | AF11: 0.21 | AG11: 0.26 | AH11: 0.31 | AI11: 0.36 | AJ11: 0.41 | AK11: 0.47 | AL11: 0.52
A12: 1000 | B12: 0.18 | C12: 0.21 | D12: 0.24 | E12: 0.27 | F12: 0.3 | G12: 0.33 | H12: 0.36 | I12: 0.39 | J12: 0.42 | K12: 0.45 | L12: 0.48 | N12: 1000 | O12: -0.02 | P12: -0.02 | Q12: 0 | R12: 0.01 | S12: 0.03 | T12: 0.05 | U12: 0.07 | V12: 0.08 | W12: 0.1 | X12: 0.12 | Y12: 0.13 | AA12: 1000 | AB12: 0 | AC12: 0.06 | AD12: 0.11 | AE12: 0.17 | AF12: 0.22 | AG12: 0.28 | AH12: 0.33 | AI12: 0.39 | AJ12: 0.44 | AK12: 0.5 | AL12: 0.55
A13: 1100 | B13: 0.16 | C13: 0.19 | D13: 0.22 | E13: 0.25 | F13: 0.28 | G13: 0.31 | H13: 0.34 | I13: 0.37 | J13: 0.41 | K13: 0.44 | L13: 0.47 | N13: 1100 | O13: -0.03 | P13: -0.03 | Q13: -0.01 | R13: 0 | S13: 0.02 | T13: 0.04 | U13: 0.06 | V13: 0.08 | W13: 0.1 | X13: 0.11 | Y13: 0.13 | AA13: 1100 | AB13: 0 | AC13: 0.06 | AD13: 0.12 | AE13: 0.18 | AF13: 0.23 | AG13: 0.29 | AH13: 0.35 | AI13: 0.41 | AJ13: 0.47 | AK13: 0.53 | AL13: 0.58
A14: 1200 | B14: 0.13 | C14: 0.17 | D14: 0.2 | E14: 0.23 | F14: 0.26 | G14: 0.3 | H14: 0.33 | I14: 0.36 | J14: 0.39 | K14: 0.43 | L14: 0.45 | N14: 1200 | O14: -0.06 | P14: -0.04 | Q14: -0.02 | R14: 0 | S14: 0.02 | T14: 0.03 | U14: 0.05 | V14: 0.07 | W14: 0.09 | X14: 0.11 | Y14: 0.13 | AA14: 1200 | AB14: 0 | AC14: 0.06 | AD14: 0.12 | AE14: 0.18 | AF14: 0.25 | AG14: 0.31 | AH14: 0.37 | AI14: 0.43 | AJ14: 0.49 | AK14: 0.55 | AL14: 0.61
... A16: 1400 | B16: 0.09 | C16: 0.13 | D16: 0.16 | E16: 0.2 | F16: 0.23 | G16: 0.27 | H16: 0.3 | I16: 0.34 | J16: 0.37 | K16: 0.41 | L16: 0.45 | N16: 1400 | O16: -0.08 | P16: -0.06 | Q16: -0.04 | R16: -0.02 | S16: 0 | T16: 0.02 | U16: 0.04 | V16: 0.07 | W16: 0.09 | X16: 0.11 | Y16: 0.13 | AA16: 1400 | AB16: 0 | AC16: 0.07 | AD16: 0.13 | AE16: 0.2 | AF16: 0.27 | AG16: 0.33 | AH16: 0.4 | AI16: 0.47 | AJ16: 0.53 | AK16: 0.6 | AL16: 0.67
A18: DUO H2 / 4 € | N18: DUO GNL | AA18: DUO DIESEL
A19: KMS / % VERDE | B19: 0 | C19: 10 | D19: 20 | E19: 30 | F19: 40 | G19: 50 | H19: 60 | I19: 70 | J19: 80 | K19: 90 | L19: 100 | N19: KMS / % BIO | O19: 0 | P19: 10 | Q19: 20 | R19: 30 | S19: 40 | T19: 50 | U19: 60 | V19: 70 | W19: 80 | X19: 90 | Y19: 100 | AA19: KMS / % HVO | AB19: 0 | AC19: 10 | AD19: 20 | AE19: 30 | AF19: 40 | AG19: 50 | AH19: 60 | AI19: 70 | AJ19: 80 | AK19: 90 | AL19: 100
A20: 100 | B20: -0.02 | C20: -0.02 | D20: -0.01 | E20: -0.01 | F20: 0 | G20: 0 | H20: 0.01 | I20: 0.01 | J20: 0.02 | K20: 0.02 | L20: 0.03 | N20: 100 | O20: -0.31 | P20: -0.31 | Q20: -0.31 | R20: -0.31 | S20: -0.3 | T20: -0.3 | U20: -0.3 | V20: -0.3 | W20: -0.29 | X20: -0.29 | Y20: -0.29 | AA20: 100 | AB20: -0.33 | AC20: -0.33 | AD20: -0.31 | AE20: -0.3 | AF20: -0.3 | AG20: -0.29 | AH20: -0.28 | AI20: -0.27 | AJ20: -0.26 | AK20: -0.25 | AL20: -0.24
A21: 200 | B21: -0.07 | C21: -0.06 | D21: -0.05 | E21: -0.04 | F21: -0.04 | G21: -0.03 | H21: -0.02 | I21: -0.01 | J21: 0 | K21: 0.01 | L21: 0.02 | N21: 200 | O21: -0.33 | P21: -0.33 | Q21: -0.32 | R21: -0.32 | S21: -0.31 | T21: -0.31 | U21: -0.3 | V21: -0.3 | W21: -0.29 | X21: -0.29 | Y21: -0.28 | AA21: 200 | AB21: -0.33 | AC21: -0.33 | AD21: -0.29 | AE21: -0.28 | AF21: -0.26 | AG21: -0.25 | AH21: -0.23 | AI21: -0.21 | AJ21: -0.2 | AK21: -0.18 | AL21: -0.16
A22: 300 | B22: -0.11 | C22: -0.1 | D22: -0.09 | E22: -0.08 | F22: -0.07 | G22: -0.05 | H22: -0.04 | I22: -0.03 | J22: -0.02 | K22: -0.01 | L22: 0.01 | N22: 300 | O22: -0.35 | P22: -0.34 | Q22: -0.33 | R22: -0.33 | S22: -0.32 | T22: -0.31 | U22: -0.3 | V22: -0.3 | W22: -0.29 | X22: -0.28 | Y22: -0.28 | AA22: 300 | AB22: -0.32 | AC22: -0.3 | AD22: -0.28 | AE22: -0.26 | AF22: -0.23 | AG22: -0.21 | AH22: -0.19 | AI22: -0.17 | AJ22: -0.14 | AK22: -0.12 | AL22: -0.1
A23: 400 | B23: -0.15 | C23: -0.13 | D23: -0.12 | E23: -0.1 | F23: -0.09 | G23: -0.08 | H23: -0.06 | I23: -0.05 | J23: -0.03 | K23: -0.02 | L23: 0 | N23: 400 | O23: -0.36 | P23: -0.35 | Q23: -0.34 | R23: -0.33 | S23: -0.32 | T23: -0.31 | U23: -0.31 | V23: -0.3 | W23: -0.29 | X23: -0.28 | Y23: -0.27 | AA23: 400 | AB23: -0.32 | AC23: -0.29 | AD23: -0.26 | AE23: -0.24 | AF23: -0.21 | AG23: -0.18 | AH23: -0.15 | AI23: -0.13 | AJ23: -0.1 | AK23: -0.07 | AL23: -0.04
A24: 500 | B24: -0.18 | C24: -0.16 | D24: -0.15 | E24: -0.13 | F24: -0.11 | G24: -0.09 | H24: -0.08 | I24: -0.06 | J24: -0.04 | K24: -0.03 | L24: -0.01 | N24: 500 | O24: -0.37 | P24: -0.36 | Q24: -0.35 | R24: -0.34 | S24: -0.33 | T24: -0.32 | U24: -0.31 | V24: -0.3 | W24: -0.29 | X24: -0.28 | Y24: -0.27 | AA24: 500 | AB24: -0.32 | AC24: -0.28 | AD24: -0.25 | AE24: -0.22 | AF24: -0.19 | AG24: -0.16 | AH24: -0.12 | AI24: -0.09 | AJ24: -0.06 | AK24: -0.03 | AL24: 0.01
A25: 600 | B25: -0.21 | C25: -0.19 | D25: -0.17 | E25: -0.15 | F25: -0.13 | G25: -0.11 | H25: -0.09 | I25: -0.07 | J25: -0.05 | K25: -0.03 | L25: -0.01 | N25: 600 | O25: -0.38 | P25: -0.37 | Q25: -0.36 | R25: -0.34 | S25: -0.33 | T25: -0.32 | U25: -0.31 | V25: -0.3 | W25: -0.29 | X25: -0.28 | Y25: -0.26 | AA25: 600 | AB25: -0.31 | AC25: -0.28 | AD25: -0.24 | AE25: -0.21 | AF25: -0.17 | AG25: -0.13 | AH25: -0.1 | AI25: -0.06 | AJ25: -0.02 | AK25: 0.01 | AL25: 0.05
A26: 700 | B26: -0.23 | C26: -0.21 | D26: -0.19 | E26: -0.17 | F26: -0.15 | G26: -0.13 | H26: -0.1 | I26: -0.08 | J26: -0.06 | K26: -0.04 | L26: -0.02 | N26: 700 | O26: -0.39 | P26: -0.37 | Q26: -0.36 | R26: -0.35 | S26: -0.34 | T26: -0.32 | U26: -0.31 | V26: -0.3 | W26: -0.29 | X26: -0.27 | Y26: -0.26 | AA26: 700 | AB26: -0.31 | AC26: -0.27 | AD26: -0.23 | AE26: -0.19 | AF26: -0.15 | AG26: -0.11 | AH26: -0.07 | AI26: -0.03 | AJ26: 0.01 | AK26: 0.05 | AL26: 0.09
A27: 800 | B27: -0.3 | C27: -0.28 | D27: -0.26 | E27: -0.24 | F27: -0.22 | G27: -0.21 | H27: -0.19 | I27: -0.17 | J27: -0.15 | K27: -0.14 | L27: -0.12 | N27: 800 | O27: -0.41 | P27: -0.4 | Q27: -0.39 | R27: -0.37 | S27: -0.36 | T27: -0.35 | U27: -0.34 | V27: -0.33 | W27: -0.32 | X27: -0.31 | Y27: -0.3 | AA27: 800 | AB27: -0.34 | AC27: -0.31 | AD27: -0.27 | AE27: -0.24 | AF27: -0.21 | AG27: -0.17 | AH27: -0.14 | AI27: -0.11 | AJ27: -0.07 | AK27: -0.04 | AL27: 0
A28: 900 | B28: -0.31 | C28: -0.29 | D28: -0.27 | E28: -0.25 | F28: -0.23 | G28: -0.21 | H28: -0.19 | I28: -0.17 | J28: -0.16 | K28: -0.14 | L28: -0.12 | N28: 900 | O28: -0.41 | P28: -0.4 | Q28: -0.39 | R28: -0.38 | S28: -0.37 | T28: -0.35 | U28: -0.34 | V28: -0.33 | W28: -0.32 | X28: -0.31 | Y28: -0.3 | AA28: 900 | AB28: -0.34 | AC28: -0.3 | AD28: -0.27 | AE28: -0.23 | AF28: -0.19 | AG28: -0.16 | AH28: -0.12 | AI28: -0.08 | AJ28: -0.05 | AK28: -0.01 | AL28: 0.02
A29: 1000 | B29: -0.32 | C29: -0.3 | D29: -0.28 | E29: -0.26 | F29: -0.24 | G29: -0.22 | H29: -0.2 | I29: -0.18 | J29: -0.16 | K29: -0.14 | L29: -0.12 | N29: 1000 | O29: -0.42 | P29: -0.4 | Q29: -0.39 | R29: -0.38 | S29: -0.37 | T29: -0.35 | U29: -0.34 | V29: -0.33 | W29: -0.32 | X29: -0.31 | Y29: -0.29 | AA29: 1000 | AB29: -0.34 | AC29: -0.3 | AD29: -0.26 | AE29: -0.22 | AF29: -0.18 | AG29: -0.14 | AH29: -0.1 | AI29: -0.07 | AJ29: -0.03 | AK29: 0.01 | AL29: 0.05
A30: 1100 | B30: -0.33 | C30: -0.31 | D30: -0.29 | E30: -0.27 | F30: -0.25 | G30: -0.22 | H30: -0.2 | I30: -0.18 | J30: -0.16 | K30: -0.14 | L30: -0.12 | N30: 1100 | O30: -0.42 | P30: -0.41 | Q30: -0.39 | R30: -0.38 | S30: -0.37 | T30: -0.35 | U30: -0.34 | V30: -0.33 | W30: -0.32 | X30: -0.3 | Y30: -0.29 | AA30: 1100 | AB30: -0.33 | AC30: -0.29 | AD30: -0.25 | AE30: -0.21 | AF30: -0.17 | AG30: -0.13 | AH30: -0.09 | AI30: -0.05 | AJ30: -0.01 | AK30: 0.03 | AL30: 0.08
A31: 1200 | B31: -0.34 | C31: -0.32 | D31: -0.3 | E31: -0.28 | F31: -0.25 | G31: -0.23 | H31: -0.21 | I31: -0.18 | J31: -0.16 | K31: -0.14 | L31: -0.12 | N31: 1200 | O31: -0.42 | P31: -0.41 | Q31: -0.4 | R31: -0.38 | S31: -0.37 | T31: -0.36 | U31: -0.34 | V31: -0.33 | W31: -0.31 | X31: -0.3 | Y31: -0.29 | AA31: 1200 | AB31: -0.33 | AC31: -0.29 | AD31: -0.25 | AE31: -0.2 | AF31: -0.16 | AG31: -0.12 | AH31: -0.07 | AI31: -0.03 | AJ31: 0.01 | AK31: 0.06 | AL31: 0.1
... A33: 1400 | B33: -0.36 | C33: -0.34 | D33: -0.31 | E33: -0.29 | F33: -0.26 | G33: -0.24 | H33: -0.21 | I33: -0.19 | J33: -0.16 | K33: -0.14 | L33: -0.11 | N33: 1400 | O33: -0.43 | P33: -0.41 | Q33: -0.4 | R33: -0.39 | S33: -0.37 | T33: -0.36 | U33: -0.34 | V33: -0.33 | W33: -0.31 | X33: -0.3 | Y33: -0.28 | AA33: 1400 | AB33: -0.33 | AC33: -0.28 | AD33: -0.24 | AE33: -0.19 | AF33: -0.14 | AG33: -0.09 | AH33: -0.05 | AI33: 0 | AJ33: 0.05 | AK33: 0.09 | AL33: 0.14
A37: TABLAS NO DINÁMICAS
A38: SIN SUBVENCIÓN | B38: 100 KMS/DIA | C38: 200 KMS/DIA | D38: 300 KMS/DIA | E38: 400 KMS/DIA | F38: 500 KMS/DIA | G38: 600 KMS/DIA | H38: 700 KMS/DIA | I38: 800 KMS/DIA | J38: 900 KMS/DIA | K38: 1000 KMS/DIA | L38: 1100 KMS/DIA | M38: 1200 KMS/DIA | N38: 1300 KMS/DIA | O38: 1400 KMS/DIA | T38: =1.5/0.9 -> 1.6666667
A39: H2 (5 €) | B39: =5.93 -> 5.93 | C39: 3.18 | D39: 2.27 | E39: 1.81 | F39: 1.54 | G39: 1.35 | H39: 1.22 | I39: 1.32 | J39: 1.22 | K39: 1.14 | L39: 1.08 | M39: 1.03 | N39: 0.98 | O39: 0.94 | T39: =T38*0.3 -> 0.5
A40: H2 (4 €) | B40: 5.85 | C40: 3.1 | D40: 2.19 | E40: 1.73 | F40: 1.45 | G40: 1.27 | H40: 1.14 | I40: 1.24 | J40: 1.14 | K40: 1.06 | L40: 1 | M40: 0.94 | N40: 0.9 | O40: 0.86
A41: H2 (3 €) | B41: 5.76 | C41: 3.02 | D41: 2.1 | E41: 1.64 | F41: 1.37 | G41: 1.19 | H41: 1.06 | I41: 1.16 | J41: 1.06 | K41: 0.98 | L41: 0.91 | M41: 0.86 | N41: 0.81 | O41: 0.78
A42: H2 (2 €) | B42: 5.68 | C42: 2.93 | D42: 2.02 | E42: 1.56 | F42: 1.29 | G42: 1.1 | H42: 0.97 | I42: 1.07 | J42: 0.97 | K42: 0.9 | L42: 0.83 | M42: 0.78 | N42: 0.73 | O42: 0.69
A43: H2 (1 €) | B43: 5.6 | C43: 2.85 | D43: 1.94 | E43: 1.48 | F43: 1.2 | G43: 1.02 | H43: 0.89 | I43: 0.99 | J43: 0.89 | K43: 0.81 | L43: 0.75 | M43: 0.69 | N43: 0.65 | O43: 0.61 | Q43: =50/1000 -> 0.05
A44: Diesel (0,8 €) | B44: 3.12 | C44: 1.7 | D44: 1.23 | E44: 0.99 | F44: 0.85 | G44: 0.76 | H44: 0.69 | I44: 0.82 | J44: 0.76 | K44: 0.71 | L44: 0.67 | M44: 0.64 | N44: 0.61 | O44: 0.59 | Q44: =1000/0.77 -> 1298.7013
A45: GNL (0,6 €) | B45: 3.67 | C45: 1.93 | D45: 1.35 | E45: 1.06 | F45: 0.88 | G45: 0.77 | H45: 0.68 | I45: 0.82 | J45: 0.75 | K45: 0.69 | L45: 0.65 | M45: 0.61 | N45: 0.58 | O45: 0.55 | Q45: =50/Q44 -> 0.0385
A46: BIOMETANO (1,05 €) | B46: 3.79 | C46: 2.05 | D46: 1.47 | E46: 1.18 | F46: 1.01 | G46: 0.89 | H46: 0.81 | I46: 0.94 | J46: 0.87 | K46: 0.82 | L46: 0.77 | M46: 0.73 | N46: 0.7 | O46: 0.67 | Q46: =Q45/0.9 -> 0.042777778
...

Sheet GASOIL 
E2: € | F2: % | G2: €/KM
C3: KMS DIARIOS
C4: KMS ANUALES
C5: KMS mensuales | E5: ='CALCULADORA COSTES'!B14*'CALCULADORA COSTES'!B15 -> 6600
C6: GASTOS FIJOS | E6: =SUM(E7:E29) -> 3538 | F6: =E6/E$5 -> 0.53606061 | G6: =E6/E$5 -> 0.53606061
C7: Cuota TRACTORA | E7: ='CALCULADORA COSTES'!E2 -> 2000 | F7: =E7/E$5 -> 0.3030303 | G7: =E7/E$5 -> 0.3030303
C8: Seguro tract. ( a 3os + Propios+seguro mercancias) | E8: 300 | F8: =E8/E$5 -> 0.045454545 | G8: =E8/E$5 -> 0.045454545
C9: Impto circulación Tract. | E9: 18 | F9: =E9/E$5 -> 0.0027272727 | G9: =E9/E$5 -> 0.0027272727
C10: Mantenimiento Tract. | E10: 162 | F10: =E10/E$5 -> 0.024545455 | G10: =E10/E$5 -> 0.024545455
C11: Reparación Tract.+ Equipo | E11: 100 | F11: =E11/E$5 -> 0.015151515 | G11: =E11/E$5 -> 0.015151515
C12: Equipo Tract. | E12: 50 | F12: =E12/E$5 -> 0.0075757576 | G12: =E12/E$5 -> 0.0075757576
C13: Siniestro Tract. | E13: 100 | F13: =E13/E$5 -> 0.015151515 | G13: =E13/E$5 -> 0.015151515
C14: Cuota PLATAFORMA | E14: ='CALCULADORA COSTES'!B20 -> 450 | F14: =E14/E$5 -> 0.068181818 | G14: =E14/E$5 -> 0.068181818
C15: Seguro Plat | E15: 25 | F15: =E15/E$5 -> 0.0037878788 | G15: =E15/E$5 -> 0.0037878788
C16: Impto circulación Plat | E16: 18 | F16: =E16/E$5 -> 0.0027272727 | G16: =E16/E$5 -> 0.0027272727
C17: Mantenimiento Plataforma + reparación | E17: 100 | F17: =E17/E$5 -> 0.015151515 | G17: =E17/E$5 -> 0.015151515
C18: Equipo Plat | E18: 50 | F18: =E18/E$5 -> 0.0075757576 | G18: =E18/E$5 -> 0.0075757576
C19: Siniestro Plat | E19: 150 | F19: =E19/E$5 -> 0.022727273 | G19: =E19/E$5 -> 0.022727273
C20: TELÉFONO | E20: 15 | F20: =E20/E$5 -> 0.0022727273 | G20: =E20/E$5 -> 0.0022727273
C21: Camb Cont (gtos fros) | F21: =E21/E$5 -> 0 | G21: =E21/E$5 -> 0
C22: Relaciones Públicas | F22: =E22/E$5 -> 0 | G22: =E22/E$5 -> 0
C23: Gastos Var. | F23: =E23/E$5 -> 0 | G23: =E23/E$5 -> 0
C24: Amortización Cont. | F24: =E24/E$5 -> 0 | G24: =E24/E$5 -> 0
C25: Mantenimiento (Gruas) | F25: =E25/E$5 -> 0 | G25: =E25/E$5 -> 0
C26: Suministros | F26: =E26/E$5 -> 0 | G26: =E26/E$5 -> 0
C27: Compras | F27: =E27/E$5 -> 0 | G27: =E27/E$5 -> 0
C28: PARKING | F28: =E28/E$5 -> 0 | G28: =E28/E$5 -> 0
C29: Reg. Cierre | F29: =E29/E$5 -> 0 | G29: =E29/E$5 -> 0
C30: GASTOS VARIABLES | E30: =SUM(E31:E37) -> 5130.64 | F30: =E30/E5 -> 0.7773697 | G30: =SUM(G31:G37) -> 0.7773697
C31: GASTO PERSONAL | D31: ='CALCULADORA COSTES'!B17*'CALCULADORA COSTES'!B16 -> 3048 | E31: =D31 -> 3048 | F31: =E31/E5 -> 0.46181818 | G31: =E31/E5 -> 0.46181818
D32: º | F32: =E32/E5 -> 0 | G32: =E32/E5 -> 0
C33: GASOIL (0,8 €/ltr) (31,5 L/100) | D33: ='CALCULADORA COSTES'!B2*'CALCULADORA COSTES'!C2 -> 0.28 | E33: =+D33*E5 -> 1848 | F33: =E33/E5 -> 0.28 | G33: =E33/E5 -> 0.28
C34: AUTOPISTA | E34: ='CALCULADORA COSTES'!E24*'CALCULADORA COSTES'!E25 -> 0 | F34: =E34/E5 -> 0 | G34: =E34/E5 -> 0
C35: NEUMÁTICOS TRACT.(0,0105€/km) | D35: 0.0102 | E35: =+D35*E5 -> 67.32 | F35: =E35/E5 -> 0.0102 | G35: =E35/E5 -> 0.0102
C36: NEUMÁTICOS PLAT. (0,0105€/km) | D36: 0.0102 | E36: =+D36*E5 -> 67.32 | F36: =E36/E5 -> 0.0102 | G36: =E36/E5 -> 0.0102
C37: OTROS GASTOS | E37: 100 | F37: =E37/E5 -> 0.015151515 | G37: =E37/E5 -> 0.015151515
C40: COSTE TOTAL | E40: =E30+E6 -> 8668.64 | F40: 1 | G40: =SUM(G30+G6) -> 1.3134303
F41: 0 | G41: 0
C42: Planificación Flota | E42: 275 | F42: =E42/E5 -> 0.041666667 | G42: =E42/E5 -> 0.041666667
C43: margen | D43: 0.04 | E43: =+E40*0.04 -> 346.7456 | F43: =E43/E5 -> 0.052537212 | G43: =E43/E5 -> 0.052537212
...

Sheet GAS NATURAL
C1: CAMIONES DE GAS
E2: € | F2: % | G2: €/KM
C3: KMS DIARIOS
C4: KMS ANUALES
C5: KMS mensuales | E5: ='CALCULADORA COSTES'!B14*'CALCULADORA COSTES'!B15 -> 6600
C6: GASTOS FIJOS | E6: =SUM(E7:E29) -> 4109 | F6: =E6/E$5 -> 0.62257576 | G6: =E6/E$5 -> 0.62257576
C7: Cuota TRACTORA | E7: ='CALCULADORA COSTES'!E3 -> 2400 | F7: =E7/E$5 -> 0.36363636 | G7: =E7/E$5 -> 0.36363636
C8: Seguro tract. ( a 3os + Propios+seguro mercancias) | E8: 300 | F8: =E8/E$5 -> 0.045454545 | G8: =E8/E$5 -> 0.045454545
C9: Impto circulación Tract. | E9: 18 | F9: =E9/E$5 -> 0.0027272727 | G9: =E9/E$5 -> 0.0027272727
C10: Mantenimiento Tract. | E10: 348 | F10: =E10/E$5 -> 0.052727273 | G10: =E10/E$5 -> 0.052727273
C11: Reparación Tract.+ Equipo | E11: 100 | F11: =E11/E$5 -> 0.015151515 | G11: =E11/E$5 -> 0.015151515
C12: Equipo Tract. | E12: 50 | F12: =E12/E$5 -> 0.0075757576 | G12: =E12/E$5 -> 0.0075757576
C13: Siniestro Tract. | E13: 100 | F13: =E13/E$5 -> 0.015151515 | G13: =E13/E$5 -> 0.015151515
C14: Cuota PLATAFORMA | E14: ='CALCULADORA COSTES'!B20 -> 450 | F14: =E14/E$5 -> 0.068181818 | G14: =E14/E$5 -> 0.068181818
C15: Seguro Plat | E15: 25 | F15: =E15/E$5 -> 0.0037878788 | G15: =E15/E$5 -> 0.0037878788
C16: Impto circulación Plat | E16: 18 | F16: =E16/E$5 -> 0.0027272727 | G16: =E16/E$5 -> 0.0027272727
C17: Mantenimiento Plataforma + reparación | E17: 150 | F17: =E17/E$5 -> 0.022727273 | G17: =E17/E$5 -> 0.022727273
C18: Equipo Plat | E18: 50 | F18: =E18/E$5 -> 0.0075757576 | G18: =E18/E$5 -> 0.0075757576
C19: Siniestro Plat | E19: 85 | F19: =E19/E$5 -> 0.012878788 | G19: =E19/E$5 -> 0.012878788
C20: TELÉFONO | E20: 15 | F20: =E20/E$5 -> 0.0022727273 | G20: =E20/E$5 -> 0.0022727273
C21: Camb Cont (gtos fros) | F21: =E21/E$5 -> 0 | G21: =E21/E$5 -> 0
C22: Relaciones Públicas | F22: =E22/E$5 -> 0 | G22: =E22/E$5 -> 0
C23: Gastos Var. | F23: =E23/E$5 -> 0 | G23: =E23/E$5 -> 0
C24: Amortización Cont. | F24: =E24/E$5 -> 0 | G24: =E24/E$5 -> 0
C25: Mantenimiento (Gruas) | F25: =E25/E$5 -> 0 | G25: =E25/E$5 -> 0
C26: Suministros | F26: =E26/E$5 -> 0 | G26: =E26/E$5 -> 0
C27: Compras | F27: =E27/E$5 -> 0 | G27: =E27/E$5 -> 0
C28: PARKING | E28: 0 | F28: =E28/E$5 -> 0 | G28: =E28/E$5 -> 0
C29: Reg. Cierre | F29: =E29/E$5 -> 0 | G29: =E29/E$5 -> 0
C30: GASTOS VARIABLES | E30: =SUM(E31:E36) -> 6394.48 | F30: =E30/E5 -> 0.96886061 | G30: =SUM(G31:G36) -> 0.96886061
C31: GASTO PERSONAL | D31: ='CALCULADORA COSTES'!B17*'CALCULADORA COSTES'!B16 -> 3048 | E31: =D31*(1+'CALCULADORA COSTES'!E26) -> 3200.4 | F31: =E31/E5 -> 0.48490909 | G31: =E31/E5 -> 0.48490909
C32: GAS | D32: ='CALCULADORA COSTES'!B3*'CALCULADORA COSTES'!C3 -> 0.4488 | E32: =+D32*E5 -> 2962.08 | F32: =E32/E5 -> 0.4488 | G32: =E32/E5 -> 0.4488
C33: AUTOPISTA | D33: =0 -> 0 | E33: ='CALCULADORA COSTES'!E24*'CALCULADORA COSTES'!E25 -> 0 | F33: =E33/E5 -> 0 | G33: =E33/E5 -> 0
C34: NEUMÁTICOS TRACT.(0,0105€/km) | D34: 0.01 | E34: =+D34*E5 -> 66 | F34: =E34/E5 -> 0.01 | G34: =E34/E5 -> 0.01
C35: NEUMÁTICOS PLAT. (0,0105€/km) | D35: 0.01 | E35: =+D35*E5 -> 66 | F35: =E35/E5 -> 0.01 | G35: =E35/E5 -> 0.01
C36: OTROS GASTOS | E36: 100 | F36: =E36/E5 -> 0.015151515 | G36: =E36/E5 -> 0.015151515
C39: COSTE TOTAL | E39: =E30+E6 -> 10503.48 | F39: 1 | G39: =SUM(G30+G6) -> 1.5914364
F40: 0 | G40: 0
C41: Planificación Flota | E41: 275 | F41: =E41/E5 -> 0.041666667 | G41: =E41/E5 -> 0.041666667
C42: margen | D42: 0.04 | E42: =+E39*0.04 -> 420.1392 | F42: =E42/E5 -> 0.063657455 | G42: =E42/E5 -> 0.063657455
...

Sheet H2
C1: CAMIONES DE GAS
E2: € | F2: % | G2: €/KM
C3: KMS DIARIOS
C4: KMS ANUALES
C5: KMS mensuales | E5: ='CALCULADORA COSTES'!B14*'CALCULADORA COSTES'!B15 -> 6600
C6: GASTOS FIJOS | E6: =SUM(E7:E29) -> 7909 | F6: =E6/E$5 -> 1.1983333 | G6: =E6/E$5 -> 1.1983333
C7: Cuota TRACTORA | E7: ='CALCULADORA COSTES'!E4 -> 6200 | F7: =E7/E$5 -> 0.93939394 | G7: =E7/E$5 -> 0.93939394
C8: Seguro tract. ( a 3os + Propios+seguro mercancias) | E8: 300 | F8: =E8/E$5 -> 0.045454545 | G8: =E8/E$5 -> 0.045454545
C9: Impto circulación Tract. | E9: 18 | F9: =E9/E$5 -> 0.0027272727 | G9: =E9/E$5 -> 0.0027272727
C10: Mantenimiento Tract. | E10: 348 | F10: =E10/E$5 -> 0.052727273 | G10: =E10/E$5 -> 0.052727273
C11: Reparación Tract.+ Equipo | E11: 100 | F11: =E11/E$5 -> 0.015151515 | G11: =E11/E$5 -> 0.015151515
C12: Equipo Tract. | E12: 50 | F12: =E12/E$5 -> 0.0075757576 | G12: =E12/E$5 -> 0.0075757576
C13: Siniestro Tract. | E13: 100 | F13: =E13/E$5 -> 0.015151515 | G13: =E13/E$5 -> 0.015151515
C14: Cuota PLATAFORMA | E14: ='CALCULADORA COSTES'!B20 -> 450 | F14: =E14/E$5 -> 0.068181818 | G14: =E14/E$5 -> 0.068181818
C15: Seguro Plat | E15: 25 | F15: =E15/E$5 -> 0.0037878788 | G15: =E15/E$5 -> 0.0037878788
C16: Impto circulación Plat | E16: 18 | F16: =E16/E$5 -> 0.0027272727 | G16: =E16/E$5 -> 0.0027272727
C17: Mantenimiento Plataforma + reparación | E17: 150 | F17: =E17/E$5 -> 0.022727273 | G17: =E17/E$5 -> 0.022727273
C18: Equipo Plat | E18: 50 | F18: =E18/E$5 -> 0.0075757576 | G18: =E18/E$5 -> 0.0075757576
C19: Siniestro Plat | E19: 85 | F19: =E19/E$5 -> 0.012878788 | G19: =E19/E$5 -> 0.012878788
C20: TELÉFONO | E20: 15 | F20: =E20/E$5 -> 0.0022727273 | G20: =E20/E$5 -> 0.0022727273
C21: Camb Cont (gtos fros) | F21: =E21/E$5 -> 0 | G21: =E21/E$5 -> 0
C22: Relaciones Públicas | F22: =E22/E$5 -> 0 | G22: =E22/E$5 -> 0
C23: Gastos Var. | F23: =E23/E$5 -> 0 | G23: =E23/E$5 -> 0
C24: Amortización Cont. | F24: =E24/E$5 -> 0 | G24: =E24/E$5 -> 0
C25: Mantenimiento (Gruas) | F25: =E25/E$5 -> 0 | G25: =E25/E$5 -> 0
C26: Suministros | F26: =E26/E$5 -> 0 | G26: =E26/E$5 -> 0
C27: Compras | F27: =E27/E$5 -> 0 | G27: =E27/E$5 -> 0
C28: PARKING | E28: 0 | F28: =E28/E$5 -> 0 | G28: =E28/E$5 -> 0
C29: Reg. Cierre | F29: =E29/E$5 -> 0 | G29: =E29/E$5 -> 0
C30: GASTOS VARIABLES | E30: =SUM(E31:E36) -> 7590.4 | F30: =E30/E5 -> 1.1500606 | G30: =SUM(G31:G36) -> 1.1500606
C31: GASTO PERSONAL | D31: ='CALCULADORA COSTES'!B17*'CALCULADORA COSTES'!B16 -> 3048 | E31: =D31*('CALCULADORA COSTES'!E26+1) -> 3200.4 | F31: =E31/E5 -> 0.48490909 | G31: =E31/E5 -> 0.48490909
C32: H2 | D32: ='CALCULADORA COSTES'!B4*'CALCULADORA COSTES'!C4 -> 0.63 | E32: =+D32*E5 -> 4158 | F32: =E32/E5 -> 0.63 | G32: =E32/E5 -> 0.63
C33: AUTOPISTA | E33: ='CALCULADORA COSTES'!E24*'CALCULADORA COSTES'!E25 -> 0 | F33: =E33/E5 -> 0 | G33: =E33/E5 -> 0
C34: NEUMÁTICOS TRACT.(0,0105€/km) | D34: 0.01 | E34: =+D34*E5 -> 66 | F34: =E34/E5 -> 0.01 | G34: =E34/E5 -> 0.01
C35: NEUMÁTICOS PLAT. (0,0105€/km) | D35: 0.01 | E35: =+D35*E5 -> 66 | F35: =E35/E5 -> 0.01 | G35: =E35/E5 -> 0.01
C36: OTROS GASTOS | E36: 100 | F36: =E36/E5 -> 0.015151515 | G36: =E36/E5 -> 0.015151515
C39: COSTE TOTAL | E39: =E30+E6 -> 15499.4 | F39: 1 | G39: =SUM(G30+G6) -> 2.3483939
F40: 0 | G40: 0
C41: Planificación Flota | E41: 275 | F41: =E41/E5 -> 0.041666667 | G41: =E41/E5 -> 0.041666667
C42: margen | D42: 0.04 | E42: =+E39*0.04 -> 619.976 | F42: =E42/E5 -> 0.093935758 | G42: =E42/E5 -> 0.093935758
...

Sheet HVO
E2: € | F2: % | G2: €/KM
C3: KMS DIARIOS
C4: KMS ANUALES
C5: KMS mensuales | E5: ='CALCULADORA COSTES'!B14*'CALCULADORA COSTES'!B15 -> 6600
C6: GASTOS FIJOS | E6: =SUM(E7:E29) -> 3538 | F6: =E6/E$5 -> 0.53606061 | G6: =E6/E$5 -> 0.53606061
C7: Cuota TRACTORA | E7: ='CALCULADORA COSTES'!E2 -> 2000 | F7: =E7/E$5 -> 0.3030303 | G7: =E7/E$5 -> 0.3030303
C8: Seguro tract. ( a 3os + Propios+seguro mercancias) | E8: 300 | F8: =E8/E$5 -> 0.045454545 | G8: =E8/E$5 -> 0.045454545
C9: Impto circulación Tract. | E9: 18 | F9: =E9/E$5 -> 0.0027272727 | G9: =E9/E$5 -> 0.0027272727
C10: Mantenimiento Tract. | E10: 162 | F10: =E10/E$5 -> 0.024545455 | G10: =E10/E$5 -> 0.024545455
C11: Reparación Tract.+ Equipo | E11: 100 | F11: =E11/E$5 -> 0.015151515 | G11: =E11/E$5 -> 0.015151515
C12: Equipo Tract. | E12: 50 | F12: =E12/E$5 -> 0.0075757576 | G12: =E12/E$5 -> 0.0075757576
C13: Siniestro Tract. | E13: 100 | F13: =E13/E$5 -> 0.015151515 | G13: =E13/E$5 -> 0.015151515
C14: Cuota PLATAFORMA | E14: ='CALCULADORA COSTES'!B20 -> 450 | F14: =E14/E$5 -> 0.068181818 | G14: =E14/E$5 -> 0.068181818
C15: Seguro Plat | E15: 25 | F15: =E15/E$5 -> 0.0037878788 | G15: =E15/E$5 -> 0.0037878788
C16: Impto circulación Plat | E16: 18 | F16: =E16/E$5 -> 0.0027272727 | G16: =E16/E$5 -> 0.0027272727
C17: Mantenimiento Plataforma + reparación | E17: 100 | F17: =E17/E$5 -> 0.015151515 | G17: =E17/E$5 -> 0.015151515
C18: Equipo Plat | E18: 50 | F18: =E18/E$5 -> 0.0075757576 | G18: =E18/E$5 -> 0.0075757576
C19: Siniestro Plat | E19: 150 | F19: =E19/E$5 -> 0.022727273 | G19: =E19/E$5 -> 0.022727273
C20: TELÉFONO | E20: 15 | F20: =E20/E$5 -> 0.0022727273 | G20: =E20/E$5 -> 0.0022727273
C21: Camb Cont (gtos fros) | F21: =E21/E$5 -> 0 | G21: =E21/E$5 -> 0
C22: Relaciones Públicas | F22: =E22/E$5 -> 0 | G22: =E22/E$5 -> 0
C23: Gastos Var. | F23: =E23/E$5 -> 0 | G23: =E23/E$5 -> 0
C24: Amortización Cont. | F24: =E24/E$5 -> 0 | G24: =E24/E$5 -> 0
C25: Mantenimiento (Gruas) | F25: =E25/E$5 -> 0 | G25: =E25/E$5 -> 0
C26: Suministros | F26: =E26/E$5 -> 0 | G26: =E26/E$5 -> 0
C27: Compras | F27: =E27/E$5 -> 0 | G27: =E27/E$5 -> 0
C28: PARKING | F28: =E28/E$5 -> 0 | G28: =E28/E$5 -> 0
C29: Reg. Cierre | F29: =E29/E$5 -> 0 | G29: =E29/E$5 -> 0
C30: GASTOS VARIABLES | E30: =SUM(E31:E37) -> 5777.44 | F30: =E30/E5 -> 0.8753697 | G30: =SUM(G31:G37) -> 0.8753697
C31: GASTO PERSONAL | D31: ='CALCULADORA COSTES'!B17*'CALCULADORA COSTES'!B16 -> 3048 | E31: =D31 -> 3048 | F31: =E31/E5 -> 0.46181818 | G31: =E31/E5 -> 0.46181818
F32: =E32/E5 -> 0 | G32: =E32/E5 -> 0
C33: HVO | D33: ='CALCULADORA COSTES'!D7 -> 0.378 | E33: =+D33*E5 -> 2494.8 | F33: =E33/E5 -> 0.378 | G33: =E33/E5 -> 0.378
C34: AUTOPISTA | E34: ='CALCULADORA COSTES'!E24*'CALCULADORA COSTES'!E25 -> 0 | F34: =E34/E5 -> 0 | G34: =E34/E5 -> 0
C35: NEUMÁTICOS TRACT.(0,0105€/km) | D35: 0.0102 | E35: =+D35*E5 -> 67.32 | F35: =E35/E5 -> 0.0102 | G35: =E35/E5 -> 0.0102
C36: NEUMÁTICOS PLAT. (0,0105€/km) | D36: 0.0102 | E36: =+D36*E5 -> 67.32 | F36: =E36/E5 -> 0.0102 | G36: =E36/E5 -> 0.0102
C37: OTROS GASTOS | E37: 100 | F37: =E37/E5 -> 0.015151515 | G37: =E37/E5 -> 0.015151515
C40: COSTE TOTAL | E40: =E30+E6 -> 9315.44 | F40: 1 | G40: =SUM(G30+G6) -> 1.4114303
F41: 0 | G41: 0
C42: Planificación Flota | E42: 275 | F42: =E42/E5 -> 0.041666667 | G42: =E42/E5 -> 0.041666667
C43: margen | D43: 0.04 | E43: =+E40*0.04 -> 372.6176 | F43: =E43/E5 -> 0.056457212 | G43: =E43/E5 -> 0.056457212
...

Sheet BIOMETANO
C1: CAMION BIOMETANO
E2: € | F2: % | G2: €/KM
C3: KMS DIARIOS
C4: KMS ANUALES
C5: KMS mensuales | E5: ='CALCULADORA COSTES'!B14*'CALCULADORA COSTES'!B15 -> 6600
C6: GASTOS FIJOS | E6: =SUM(E7:E29) -> 4109 | F6: =E6/E$5 -> 0.62257576 | G6: =E6/E$5 -> 0.62257576
C7: Cuota TRACTORA | E7: ='CALCULADORA COSTES'!E3 -> 2400 | F7: =E7/E$5 -> 0.36363636 | G7: =E7/E$5 -> 0.36363636
C8: Seguro tract. ( a 3os + Propios+seguro mercancias) | E8: 300 | F8: =E8/E$5 -> 0.045454545 | G8: =E8/E$5 -> 0.045454545
C9: Impto circulación Tract. | E9: 18 | F9: =E9/E$5 -> 0.0027272727 | G9: =E9/E$5 -> 0.0027272727
C10: Mantenimiento Tract. | E10: 348 | F10: =E10/E$5 -> 0.052727273 | G10: =E10/E$5 -> 0.052727273
C11: Reparación Tract.+ Equipo | E11: 100 | F11: =E11/E$5 -> 0.015151515 | G11: =E11/E$5 -> 0.015151515
C12: Equipo Tract. | E12: 50 | F12: =E12/E$5 -> 0.0075757576 | G12: =E12/E$5 -> 0.0075757576
C13: Siniestro Tract. | E13: 100 | F13: =E13/E$5 -> 0.015151515 | G13: =E13/E$5 -> 0.015151515
C14: Cuota PLATAFORMA | E14: ='CALCULADORA COSTES'!B20 -> 450 | F14: =E14/E$5 -> 0.068181818 | G14: =E14/E$5 -> 0.068181818
C15: Seguro Plat | E15: 25 | F15: =E15/E$5 -> 0.0037878788 | G15: =E15/E$5 -> 0.0037878788
C16: Impto circulación Plat | E16: 18 | F16: =E16/E$5 -> 0.0027272727 | G16: =E16/E$5 -> 0.0027272727
C17: Mantenimiento Plataforma + reparación | E17: 150 | F17: =E17/E$5 -> 0.022727273 | G17: =E17/E$5 -> 0.022727273
C18: Equipo Plat | E18: 50 | F18: =E18/E$5 -> 0.0075757576 | G18: =E18/E$5 -> 0.0075757576
C19: Siniestro Plat | E19: 85 | F19: =E19/E$5 -> 0.012878788 | G19: =E19/E$5 -> 0.012878788
C20: TELÉFONO | E20: 15 | F20: =E20/E$5 -> 0.0022727273 | G20: =E20/E$5 -> 0.0022727273
C21: Camb Cont (gtos fros) | F21: =E21/E$5 -> 0 | G21: =E21/E$5 -> 0
C22: Relaciones Públicas | F22: =E22/E$5 -> 0 | G22: =E22/E$5 -> 0
C23: Gastos Var. | F23: =E23/E$5 -> 0 | G23: =E23/E$5 -> 0
C24: Amortización Cont. | F24: =E24/E$5 -> 0 | G24: =E24/E$5 -> 0
C25: Mantenimiento (Gruas) | F25: =E25/E$5 -> 0 | G25: =E25/E$5 -> 0
C26: Suministros | F26: =E26/E$5 -> 0 | G26: =E26/E$5 -> 0
C27: Compras | F27: =E27/E$5 -> 0 | G27: =E27/E$5 -> 0
C28: PARKING | E28: 0 | F28: =E28/E$5 -> 0 | G28: =E28/E$5 -> 0
C29: Reg. Cierre | F29: =E29/E$5 -> 0 | G29: =E29/E$5 -> 0
C30: GASTOS VARIABLES | E30: =SUM(E31:E36) -> 6569.056 | F30: =E30/E5 -> 0.99531152 | G30: =SUM(G31:G36) -> 0.99531152
C31: GASTO PERSONAL | D31: =(2000+85+22*36.06+20+150)*'CALCULADORA COSTES'!B16 -> 3048.32 | E31: =D31*(1+'CALCULADORA COSTES'!E26) -> 3200.736 | F31: =E31/E5 -> 0.48496 | G31: =E31/E5 -> 0.48496
C32: GAS (0,6 €/KG) (26,40 K/100) | D32: ='CALCULADORA COSTES'!B5*'CALCULADORA COSTES'!C5 -> 0.4752 | E32: =+D32*E5 -> 3136.32 | F32: =E32/E5 -> 0.4752 | G32: =E32/E5 -> 0.4752
C33: AUTOPISTA | D33: =0 -> 0 | E33: ='CALCULADORA COSTES'!E24*'CALCULADORA COSTES'!E25 -> 0 | F33: =E33/E5 -> 0 | G33: =E33/E5 -> 0
C34: NEUMÁTICOS TRACT.(0,0105€/km) | D34: 0.01 | E34: =+D34*E5 -> 66 | F34: =E34/E5 -> 0.01 | G34: =E34/E5 -> 0.01
C35: NEUMÁTICOS PLAT. (0,0105€/km) | D35: 0.01 | E35: =+D35*E5 -> 66 | F35: =E35/E5 -> 0.01 | G35: =E35/E5 -> 0.01
C36: OTROS GASTOS | E36: 100 | F36: =E36/E5 -> 0.015151515 | G36: =E36/E5 -> 0.015151515
C39: COSTE TOTAL | E39: =E30+E6 -> 10678.056 | F39: 1 | G39: =SUM(G30+G6) -> 1.6178873
F40: 0 | G40: 0
C41: Planificación Flota | E41: 275 | F41: =E41/E5 -> 0.041666667 | G41: =E41/E5 -> 0.041666667
C42: margen | D42: 0.04 | E42: =+E39*0.04 -> 427.12224 | F42: =E42/E5 -> 0.064715491 | G42: =E42/E5 -> 0.064715491
...

Sheet ELÉCTRICO
C1: CAMIONES DE GAS
E2: € | F2: % | G2: €/KM
C3: KMS DIARIOS
C4: KMS ANUALES
C5: KMS mensuales | E5: ='CALCULADORA COSTES'!B14*'CALCULADORA COSTES'!B15 -> 6600
C6: GASTOS FIJOS | E6: =SUM(E7:E29) -> 5705 | F6: =E6/E$5 -> 0.86439394 | G6: =E6/E$5 -> 0.86439394
C7: Cuota TRACTORA | E7: ='CALCULADORA COSTES'!$E6 -> 4000 | F7: =E7/E$5 -> 0.60606061 | G7: =E7/E$5 -> 0.60606061
C8: Seguro tract. ( a 3os + Propios+seguro mercancias) | E8: 300 | F8: =E8/E$5 -> 0.045454545 | G8: =E8/E$5 -> 0.045454545
C9: Impto circulación Tract. | E9: 18 | F9: =E9/E$5 -> 0.0027272727 | G9: =E9/E$5 -> 0.0027272727
C10: Mantenimiento Tract. | E10: 348 | F10: =E10/E$5 -> 0.052727273 | G10: =E10/E$5 -> 0.052727273
C11: Reparación Tract.+ Equipo | E11: 100 | F11: =E11/E$5 -> 0.015151515 | G11: =E11/E$5 -> 0.015151515
C12: Equipo Tract. | E12: 50 | F12: =E12/E$5 -> 0.0075757576 | G12: =E12/E$5 -> 0.0075757576
C13: Siniestro Tract. | E13: 100 | F13: =E13/E$5 -> 0.015151515 | G13: =E13/E$5 -> 0.015151515
C14: Cuota PLATAFORMA | E14: ='CALCULADORA COSTES'!B20 -> 450 | F14: =E14/E$5 -> 0.068181818 | G14: =E14/E$5 -> 0.068181818
C15: Seguro Plat | E15: 25 | F15: =E15/E$5 -> 0.0037878788 | G15: =E15/E$5 -> 0.0037878788
C16: Impto circulación Plat | E16: 18 | F16: =E16/E$5 -> 0.0027272727 | G16: =E16/E$5 -> 0.0027272727
C17: Mantenimiento Plataforma + reparación | E17: 150 | F17: =E17/E$5 -> 0.022727273 | G17: =E17/E$5 -> 0.022727273
C18: Equipo Plat | E18: 50 | F18: =E18/E$5 -> 0.0075757576 | G18: =E18/E$5 -> 0.0075757576
C19: Siniestro Plat | E19: 85 | F19: =E19/E$5 -> 0.012878788 | G19: =E19/E$5 -> 0.012878788
C20: TELÉFONO | E20: 11 | F20: =E20/E$5 -> 0.0016666667 | G20: =E20/E$5 -> 0.0016666667
C21: Camb Cont (gtos fros) | F21: =E21/E$5 -> 0 | G21: =E21/E$5 -> 0
C22: Relaciones Públicas | F22: =E22/E$5 -> 0 | G22: =E22/E$5 -> 0
C23: Gastos Var. | F23: =E23/E$5 -> 0 | G23: =E23/E$5 -> 0
C24: Amortización Cont. | F24: =E24/E$5 -> 0 | G24: =E24/E$5 -> 0
C25: Mantenimiento (Gruas) | F25: =E25/E$5 -> 0 | G25: =E25/E$5 -> 0
C26: Suministros | F26: =E26/E$5 -> 0 | G26: =E26/E$5 -> 0
C27: Compras | F27: =E27/E$5 -> 0 | G27: =E27/E$5 -> 0
C28: PARKING | E28: 0 | F28: =E28/E$5 -> 0 | G28: =E28/E$5 -> 0
C29: Reg. Cierre | F29: =E29/E$5 -> 0 | G29: =E29/E$5 -> 0
C30: GASTOS VARIABLES | E30: =SUM(E31:E36) -> 6210.34 | F30: =E30/E5 -> 0.94096061 | G30: =SUM(G31:G36) -> 0.94096061
C31: GASTO PERSONAL | D31: ='CALCULADORA COSTES'!B17*'CALCULADORA COSTES'!B16 -> 3048 | E31: =D31*(1+'CALCULADORA COSTES'!E26) -> 3200.4 | F31: =E31/E5 -> 0.48490909 | G31: =E31/E5 -> 0.48490909
C32: Eléctrico | D32: ='CALCULADORA COSTES'!B6*'CALCULADORA COSTES'!C6 -> 0.4209 | E32: =D32*E5 -> 2777.94 | F32: =E32/E5 -> 0.4209 | G32: =E32/E5 -> 0.4209
C33: AUTOPISTA | E33: ='CALCULADORA COSTES'!E24*'CALCULADORA COSTES'!E25 -> 0 | F33: =E33/E5 -> 0 | G33: =E33/E5 -> 0
C34: NEUMÁTICOS TRACT.(0,0105€/km) | D34: 0.01 | E34: =+D34*E5 -> 66 | F34: =E34/E5 -> 0.01 | G34: =E34/E5 -> 0.01
C35: NEUMÁTICOS PLAT. (0,0105€/km) | D35: 0.01 | E35: =+D35*E5 -> 66 | F35: =E35/E5 -> 0.01 | G35: =E35/E5 -> 0.01
C36: OTROS GASTOS | E36: 100 | F36: =E36/E5 -> 0.015151515 | G36: =E36/E5 -> 0.015151515
C39: COSTE TOTAL | E39: =E30+E6 -> 11915.34 | F39: 1 | G39: =SUM(G30+G6) -> 1.8053545
F40: 0 | G40: 0
C41: Planificación Flota | E41: 275 | F41: =E41/E5 -> 0.041666667 | G41: =E41/E5 -> 0.041666667
C42: margen | D42: 0.04 | E42: =+E39*0.04 -> 476.6136 | F42: =E42/E5 -> 0.072214182 | G42: =E42/E5 -> 0.072214182
...

Sheet DUOTRAILER GASOIL
E2: € | F2: % | G2: €/KM
C3: KMS DIARIOS
C4: KMS ANUALES
C5: KMS mensuales | E5: ='CALCULADORA COSTES'!B14*'CALCULADORA COSTES'!B15 -> 6600
C6: GASTOS FIJOS | E6: =SUM(E7:E29) -> 5047 | F6: =E6/E$5 -> 0.76469697 | G6: =E6/E$5 -> 0.76469697
C7: Cuota TRACTORA | E7: ='CALCULADORA COSTES'!E9 -> 2200 | F7: =E7/E$5 -> 0.33333333 | G7: =E7/E$5 -> 0.33333333
C8: Seguro tract. ( a 3os + Propios+seguro mercancias) | E8: 300 | F8: =E8/E$5 -> 0.045454545 | G8: =E8/E$5 -> 0.045454545
C9: Impto circulación Tract. | E9: 18 | F9: =E9/E$5 -> 0.0027272727 | G9: =E9/E$5 -> 0.0027272727
C10: Mantenimiento Tract. | E10: 400 | F10: =E10/E$5 -> 0.060606061 | G10: =E10/E$5 -> 0.060606061
C11: Reparación Tract.+ Equipo | E11: 100 | F11: =E11/E$5 -> 0.015151515 | G11: =E11/E$5 -> 0.015151515
C12: Equipo Tract. | E12: 50 | F12: =E12/E$5 -> 0.0075757576 | G12: =E12/E$5 -> 0.0075757576
C13: Siniestro Tract. | E13: 150 | F13: =E13/E$5 -> 0.022727273 | G13: =E13/E$5 -> 0.022727273
C14: Cuota PLATAFORMA Enganche | E14: =115+'CALCULADORA COSTES'!B20 -> 565 | F14: =E14/E$5 -> 0.085606061 | G14: =E14/E$5 -> 0.085606061
C15: Seguro Plat | E15: 25 | F15: =E15/E$5 -> 0.0037878788 | G15: =E15/E$5 -> 0.0037878788
C16: Impto circulación Plat | E16: 18 | F16: =E16/E$5 -> 0.0027272727 | G16: =E16/E$5 -> 0.0027272727
C17: Mantenimiento Plataforma + reparación | E17: 125 | F17: =E17/E$5 -> 0.018939394 | G17: =E17/E$5 -> 0.018939394
C18: CUOTA DOLLY | E18: ='CALCULADORA COSTES'!C20 -> 200 | F18: =E18/E$5 -> 0.03030303 | G18: =E18/E$5 -> 0.03030303
C19: Seguro Dolly | E19: 25 | F19: =E19/E$5 -> 0.0037878788 | G19: =E19/E$5 -> 0.0037878788
C20: Impuesto Dolly | E20: 18 | F20: =E20/E$5 -> 0.0027272727 | G20: =E20/E$5 -> 0.0027272727
C21: Mantenimiento | E21: 50 | F21: =E21/E$5 -> 0.0075757576 | G21: =E21/E$5 -> 0.0075757576
C22: Cuota PLATAFORMA 2 | E22: ='CALCULADORA COSTES'!B20 -> 450 | F22: =E22/E$5 -> 0.068181818 | G22: =E22/E$5 -> 0.068181818
C23: Seguro Plat | E23: 25 | F23: =E23/E$5 -> 0.0037878788 | G23: =E23/E$5 -> 0.0037878788
C24: Impto circulación Plat | E24: 18 | F24: =E24/E$5 -> 0.0027272727 | G24: =E24/E$5 -> 0.0027272727
C25: Mantenimiento Plataforma + reparación | E25: 125 | F25: =E25/E$5 -> 0.018939394 | G25: =E25/E$5 -> 0.018939394
C26: Siniestros | E26: 170 | F26: =E26/E$5 -> 0.025757576 | G26: =E26/E$5 -> 0.025757576
C27: Teléfono | E27: 15 | F27: =E27/E$5 -> 0.0022727273 | G27: =E27/E$5 -> 0.0022727273
C28: PARKING | F28: =E28/E$5 -> 0 | G28: =E28/E$5 -> 0
C29: Reg. Cierre | F29: =E29/E$5 -> 0 | G29: =E29/E$5 -> 0
C30: GASTOS VARIABLES | E30: =SUM(E31:E37) -> 6156.88 | F30: =E30/E5 -> 0.93286061 | G30: =SUM(G31:G37) -> 0.93286061
C31: GASTO PERSONAL | D31: ='CALCULADORA COSTES'!B17*'CALCULADORA COSTES'!B16 -> 3048 | E31: ='H2'!E31 -> 3200.4 | F31: =E31/E5 -> 0.48490909 | G31: =E31/E5 -> 0.48490909
F32: =E32/E5 -> 0 | G32: =E32/E5 -> 0
C33: GASOIL (0,8 €/L) | D33: ='CALCULADORA COSTES'!B9*'CALCULADORA COSTES'!C9 -> 0.392 | E33: =+D33*E5 -> 2587.2 | F33: =E33/E5 -> 0.392 | G33: =E33/E5 -> 0.392
C34: AUTOPISTA | E34: ='CALCULADORA COSTES'!F24*'CALCULADORA COSTES'!F25 -> 0 | F34: =E34/E5 -> 0 | G34: =E34/E5 -> 0
C35: NEUMÁTICOS TRACT.(0,0105€/km) | D35: 0.0102 | E35: =+D35*E5*2 -> 134.64 | F35: =E35/E5 -> 0.0204 | G35: =E35/E5 -> 0.0204
C36: NEUMÁTICOS PLAT. (0,0105€/km) | D36: 0.0102 | E36: =+D36*E5*2 -> 134.64 | F36: =E36/E5 -> 0.0204 | G36: =E36/E5 -> 0.0204
C37: OTROS GASTOS | E37: 100 | F37: =E37/E5 -> 0.015151515 | G37: =E37/E5 -> 0.015151515
C40: COSTE TOTAL | E40: =E30+E6 -> 11203.88 | F40: 1 | G40: =SUM(G30+G6) -> 1.6975576
F41: 0 | G41: 0
C42: Planificación Flota | E42: 275 | F42: =E42/E5 -> 0.041666667 | G42: =E42/E5 -> 0.041666667
C43: margen | D43: 0.04 | E43: =+E40*0.04 -> 448.1552 | F43: =E43/E5 -> 0.067902303 | G43: =E43/E5 -> 0.067902303
...

Sheet DUOTRAILER HVO
E2: € | F2: % | G2: €/KM
C3: KMS DIARIOS
C4: KMS ANUALES
C5: KMS mensuales | E5: ='CALCULADORA COSTES'!B14*'CALCULADORA COSTES'!B15 -> 6600
C6: GASTOS FIJOS | E6: =SUM(E7:E29) -> 5047 | F6: =E6/E$5 -> 0.76469697 | G6: =E6/E$5 -> 0.76469697
C7: Cuota TRACTORA | E7: ='CALCULADORA COSTES'!E9 -> 2200 | F7: =E7/E$5 -> 0.33333333 | G7: =E7/E$5 -> 0.33333333
C8: Seguro tract. ( a 3os + Propios+seguro mercancias) | E8: 300 | F8: =E8/E$5 -> 0.045454545 | G8: =E8/E$5 -> 0.045454545
C9: Impto circulación Tract. | E9: 18 | F9: =E9/E$5 -> 0.0027272727 | G9: =E9/E$5 -> 0.0027272727
C10: Mantenimiento Tract. | E10: 400 | F10: =E10/E$5 -> 0.060606061 | G10: =E10/E$5 -> 0.060606061
C11: Reparación Tract.+ Equipo | E11: 100 | F11: =E11/E$5 -> 0.015151515 | G11: =E11/E$5 -> 0.015151515
C12: Equipo Tract. | E12: 50 | F12: =E12/E$5 -> 0.0075757576 | G12: =E12/E$5 -> 0.0075757576
C13: Siniestro Tract. | E13: 150 | F13: =E13/E$5 -> 0.022727273 | G13: =E13/E$5 -> 0.022727273
C14: Cuota PLATAFORMA Enganche | E14: ='DUOTRAILER GASOIL'!E14 -> 565 | F14: =E14/E$5 -> 0.085606061 | G14: =E14/E$5 -> 0.085606061
C15: Seguro Plat | E15: 25 | F15: =E15/E$5 -> 0.0037878788 | G15: =E15/E$5 -> 0.0037878788
C16: Impto circulación Plat | E16: 18 | F16: =E16/E$5 -> 0.0027272727 | G16: =E16/E$5 -> 0.0027272727
C17: Mantenimiento Plataforma + reparación | E17: 125 | F17: =E17/E$5 -> 0.018939394 | G17: =E17/E$5 -> 0.018939394
C18: CUOTA DOLLY | E18: ='DUOTRAILER GASOIL'!E18 -> 200 | F18: =E18/E$5 -> 0.03030303 | G18: =E18/E$5 -> 0.03030303
C19: Seguro Dolly | E19: 25 | F19: =E19/E$5 -> 0.0037878788 | G19: =E19/E$5 -> 0.0037878788
C20: Impuesto Dolly | E20: 18 | F20: =E20/E$5 -> 0.0027272727 | G20: =E20/E$5 -> 0.0027272727
C21: Mantenimiento | E21: 50 | F21: =E21/E$5 -> 0.0075757576 | G21: =E21/E$5 -> 0.0075757576
C22: Cuota PLATAFORMA 2 | E22: ='DUOTRAILER GASOIL'!E22 -> 450 | F22: =E22/E$5 -> 0.068181818 | G22: =E22/E$5 -> 0.068181818
C23: Seguro Plat | E23: 25 | F23: =E23/E$5 -> 0.0037878788 | G23: =E23/E$5 -> 0.0037878788
C24: Impto circulación Plat | E24: 18 | F24: =E24/E$5 -> 0.0027272727 | G24: =E24/E$5 -> 0.0027272727
C25: Mantenimiento Plataforma + reparación | E25: 125 | F25: =E25/E$5 -> 0.018939394 | G25: =E25/E$5 -> 0.018939394
C26: Siniestros | E26: 170 | F26: =E26/E$5 -> 0.025757576 | G26: =E26/E$5 -> 0.025757576
C27: Teléfono | E27: 15 | F27: =E27/E$5 -> 0.0022727273 | G27: =E27/E$5 -> 0.0022727273
C28: PARKING | F28: =E28/E$5 -> 0 | G28: =E28/E$5 -> 0
C29: Reg. Cierre | F29: =E29/E$5 -> 0 | G29: =E29/E$5 -> 0
C30: GASTOS VARIABLES | E30: =SUM(E31:E37) -> 7222.78 | F30: =E30/E5 -> 1.0943606 | G30: =SUM(G31:G37) -> 1.0943606
C31: GASTO PERSONAL | D31: ='CALCULADORA COSTES'!B17*'CALCULADORA COSTES'!B16 -> 3048 | E31: ='H2'!E31 -> 3200.4 | F31: =E31/E5 -> 0.48490909 | G31: =E31/E5 -> 0.48490909
F32: =E32/E5 -> 0 | G32: =E32/E5 -> 0
C33: GASOIL (0,8 €/L) | D33: ='CALCULADORA COSTES'!D11 -> 0.5535 | E33: =+D33*E5 -> 3653.1 | F33: =E33/E5 -> 0.5535 | G33: =E33/E5 -> 0.5535
C34: AUTOPISTA | E34: ='CALCULADORA COSTES'!F24*'CALCULADORA COSTES'!F25 -> 0 | F34: =E34/E5 -> 0 | G34: =E34/E5 -> 0
C35: NEUMÁTICOS TRACT.(0,0105€/km) | D35: 0.0102 | E35: =+D35*E5*2 -> 134.64 | F35: =E35/E5 -> 0.0204 | G35: =E35/E5 -> 0.0204
C36: NEUMÁTICOS PLAT. (0,0105€/km) | D36: 0.0102 | E36: =+D36*E5*2 -> 134.64 | F36: =E36/E5 -> 0.0204 | G36: =E36/E5 -> 0.0204
C37: OTROS GASTOS | E37: 100 | F37: =E37/E5 -> 0.015151515 | G37: =E37/E5 -> 0.015151515
C40: COSTE TOTAL | E40: =E30+E6 -> 12269.78 | F40: 1 | G40: =SUM(G30+G6) -> 1.8590576
F41: 0 | G41: 0
C42: Planificación Flota | E42: 275 | F42: =E42/E5 -> 0.041666667 | G42: =E42/E5 -> 0.041666667
C43: margen | D43: 0.04 | E43: =+E40*0.04 -> 490.7912 | F43: =E43/E5 -> 0.074362303 | G43: =E43/E5 -> 0.074362303
...

Sheet DUOTRAILER H2
E2: € | F2: % | G2: €/KM
C3: KMS DIARIOS
C4: KMS ANUALES
C5: KMS mensuales | E5: ='CALCULADORA COSTES'!B14*'CALCULADORA COSTES'!B15 -> 6600
C6: GASTOS FIJOS | E6: =SUM(E7:E29) -> 9047 | F6: =E6/E$5 -> 1.3707576 | G6: =E6/E$5 -> 1.3707576
C7: Cuota TRACTORA | E7: ='CALCULADORA COSTES'!E8 -> 6200 | F7: =E7/E$5 -> 0.93939394 | G7: =E7/E$5 -> 0.93939394
C8: Seguro tract. ( a 3os + Propios+seguro mercancias) | E8: 300 | F8: =E8/E$5 -> 0.045454545 | G8: =E8/E$5 -> 0.045454545
C9: Impto circulación Tract. | E9: 18 | F9: =E9/E$5 -> 0.0027272727 | G9: =E9/E$5 -> 0.0027272727
C10: Mantenimiento Tract. | E10: 400 | F10: =E10/E$5 -> 0.060606061 | G10: =E10/E$5 -> 0.060606061
C11: Reparación Tract.+ Equipo | E11: 100 | F11: =E11/E$5 -> 0.015151515 | G11: =E11/E$5 -> 0.015151515
C12: Equipo Tract. | E12: 50 | F12: =E12/E$5 -> 0.0075757576 | G12: =E12/E$5 -> 0.0075757576
C13: Siniestro Tract. | E13: 150 | F13: =E13/E$5 -> 0.022727273 | G13: =E13/E$5 -> 0.022727273
C14: Cuota PLATAFORMA Enganche | E14: ='DUOTRAILER GASOIL'!E14 -> 565 | F14: =E14/E$5 -> 0.085606061 | G14: =E14/E$5 -> 0.085606061
C15: Seguro Plat | E15: 25 | F15: =E15/E$5 -> 0.0037878788 | G15: =E15/E$5 -> 0.0037878788
C16: Impto circulación Plat | E16: 18 | F16: =E16/E$5 -> 0.0027272727 | G16: =E16/E$5 -> 0.0027272727
C17: Mantenimiento Plataforma + reparación | E17: 125 | F17: =E17/E$5 -> 0.018939394 | G17: =E17/E$5 -> 0.018939394
C18: CUOTA DOLLY | E18: ='DUOTRAILER GASOIL'!E18 -> 200 | F18: =E18/E$5 -> 0.03030303 | G18: =E18/E$5 -> 0.03030303
C19: Seguro Dolly | E19: 25 | F19: =E19/E$5 -> 0.0037878788 | G19: =E19/E$5 -> 0.0037878788
C20: Impuesto Dolly | E20: 18 | F20: =E20/E$5 -> 0.0027272727 | G20: =E20/E$5 -> 0.0027272727
C21: Mantenimiento | E21: 50 | F21: =E21/E$5 -> 0.0075757576 | G21: =E21/E$5 -> 0.0075757576
C22: Cuota PLATAFORMA 2 | E22: ='DUOTRAILER GASOIL'!E22 -> 450 | F22: =E22/E$5 -> 0.068181818 | G22: =E22/E$5 -> 0.068181818
C23: Seguro Plat | E23: 25 | F23: =E23/E$5 -> 0.0037878788 | G23: =E23/E$5 -> 0.0037878788
C24: Impto circulación Plat | E24: 18 | F24: =E24/E$5 -> 0.0027272727 | G24: =E24/E$5 -> 0.0027272727
C25: Mantenimiento Plataforma + reparación | E25: 125 | F25: =E25/E$5 -> 0.018939394 | G25: =E25/E$5 -> 0.018939394
C26: Siniestros | E26: 170 | F26: =E26/E$5 -> 0.025757576 | G26: =E26/E$5 -> 0.025757576
C27: Teléfono | E27: 15 | F27: =E27/E$5 -> 0.0022727273 | G27: =E27/E$5 -> 0.0022727273
C28: PARKING | F28: =E28/E$5 -> 0 | G28: =E28/E$5 -> 0
C29: Reg. Cierre | F29: =E29/E$5 -> 0 | G29: =E29/E$5 -> 0
C30: GASTOS VARIABLES | E30: =SUM(E31:E37) -> 9390.88 | F30: =E30/E5 -> 1.4228606 | G30: =SUM(G31:G37) -> 1.4228606
C31: GASTO PERSONAL | D31: ='CALCULADORA COSTES'!B17*'CALCULADORA COSTES'!B16 -> 3048 | E31: ='H2'!E31 -> 3200.4 | F31: =E31/E5 -> 0.48490909 | G31: =E31/E5 -> 0.48490909
F32: =E32/E5 -> 0 | G32: =E32/E5 -> 0
C33: Hidrógeno | D33: ='CALCULADORA COSTES'!B8*'CALCULADORA COSTES'!C8 -> 0.882 | E33: =+D33*E5 -> 5821.2 | F33: =E33/E5 -> 0.882 | G33: =E33/E5 -> 0.882
C34: AUTOPISTA | E34: ='CALCULADORA COSTES'!F24*'CALCULADORA COSTES'!F25 -> 0 | F34: =E34/E5 -> 0 | G34: =E34/E5 -> 0
C35: NEUMÁTICOS TRACT.(0,0105€/km) | D35: 0.0102 | E35: =+D35*E5*2 -> 134.64 | F35: =E35/E5 -> 0.0204 | G35: =E35/E5 -> 0.0204
C36: NEUMÁTICOS PLAT. (0,0105€/km) | D36: 0.0102 | E36: =+D36*E5*2 -> 134.64 | F36: =E36/E5 -> 0.0204 | G36: =E36/E5 -> 0.0204
C37: OTROS GASTOS | E37: 100 | F37: =E37/E5 -> 0.015151515 | G37: =E37/E5 -> 0.015151515
C40: COSTE TOTAL | E40: =E30+E6 -> 18437.88 | F40: 1 | G40: =SUM(G30+G6) -> 2.7936182
F41: 0 | G41: 0
C42: Planificación Flota | E42: 275 | F42: =E42/E5 -> 0.041666667 | G42: =E42/E5 -> 0.041666667
C43: margen | D43: 0.04 | E43: =+E40*0.04 -> 737.5152 | F43: =E43/E5 -> 0.11174473 | G43: =E43/E5 -> 0.11174473
...

Sheet DUOTRAILER ELECTRICO
E2: € | F2: % | G2: €/KM
C3: KMS DIARIOS
C4: KMS ANUALES
C5: KMS mensuales | E5: ='CALCULADORA COSTES'!B14*'CALCULADORA COSTES'!B15 -> 6600
C6: GASTOS FIJOS | E6: =SUM(E7:E29) -> 6847 | F6: =E6/E$5 -> 1.0374242 | G6: =E6/E$5 -> 1.0374242
C7: Cuota TRACTORA | E7: ='CALCULADORA COSTES'!E12 -> 4000 | F7: =E7/E$5 -> 0.60606061 | G7: =E7/E$5 -> 0.60606061
C8: Seguro tract. ( a 3os + Propios+seguro mercancias) | E8: 300 | F8: =E8/E$5 -> 0.045454545 | G8: =E8/E$5 -> 0.045454545
C9: Impto circulación Tract. | E9: 18 | F9: =E9/E$5 -> 0.0027272727 | G9: =E9/E$5 -> 0.0027272727
C10: Mantenimiento Tract. | E10: 400 | F10: =E10/E$5 -> 0.060606061 | G10: =E10/E$5 -> 0.060606061
C11: Reparación Tract.+ Equipo | E11: 100 | F11: =E11/E$5 -> 0.015151515 | G11: =E11/E$5 -> 0.015151515
C12: Equipo Tract. | E12: 50 | F12: =E12/E$5 -> 0.0075757576 | G12: =E12/E$5 -> 0.0075757576
C13: Siniestro Tract. | E13: 150 | F13: =E13/E$5 -> 0.022727273 | G13: =E13/E$5 -> 0.022727273
C14: Cuota PLATAFORMA Enganche | E14: ='DUOTRAILER GASOIL'!E14 -> 565 | F14: =E14/E$5 -> 0.085606061 | G14: =E14/E$5 -> 0.085606061
C15: Seguro Plat | E15: 25 | F15: =E15/E$5 -> 0.0037878788 | G15: =E15/E$5 -> 0.0037878788
C16: Impto circulación Plat | E16: 18 | F16: =E16/E$5 -> 0.0027272727 | G16: =E16/E$5 -> 0.0027272727
C17: Mantenimiento Plataforma + reparación | E17: 125 | F17: =E17/E$5 -> 0.018939394 | G17: =E17/E$5 -> 0.018939394
C18: CUOTA DOLLY | E18: ='DUOTRAILER GASOIL'!E18 -> 200 | F18: =E18/E$5 -> 0.03030303 | G18: =E18/E$5 -> 0.03030303
C19: Seguro Dolly | E19: 25 | F19: =E19/E$5 -> 0.0037878788 | G19: =E19/E$5 -> 0.0037878788
C20: Impuesto Dolly | E20: 18 | F20: =E20/E$5 -> 0.0027272727 | G20: =E20/E$5 -> 0.0027272727
C21: Mantenimiento | E21: 50 | F21: =E21/E$5 -> 0.0075757576 | G21: =E21/E$5 -> 0.0075757576
C22: Cuota PLATAFORMA 2 | E22: ='DUOTRAILER GASOIL'!E22 -> 450 | F22: =E22/E$5 -> 0.068181818 | G22: =E22/E$5 -> 0.068181818
C23: Seguro Plat | E23: 25 | F23: =E23/E$5 -> 0.0037878788 | G23: =E23/E$5 -> 0.0037878788
C24: Impto circulación Plat | E24: 18 | F24: =E24/E$5 -> 0.0027272727 | G24: =E24/E$5 -> 0.0027272727
C25: Mantenimiento Plataforma + reparación | E25: 125 | F25: =E25/E$5 -> 0.018939394 | G25: =E25/E$5 -> 0.018939394
C26: Siniestros | E26: 170 | F26: =E26/E$5 -> 0.025757576 | G26: =E26/E$5 -> 0.025757576
C27: Teléfono | E27: 15 | F27: =E27/E$5 -> 0.0022727273 | G27: =E27/E$5 -> 0.0022727273
C28: PARKING | F28: =E28/E$5 -> 0 | G28: =E28/E$5 -> 0
C29: Reg. Cierre | F29: =E29/E$5 -> 0 | G29: =E29/E$5 -> 0
C30: GASTOS VARIABLES | E30: =SUM(E31:E37) -> 5514.238 | F30: =E30/E5 -> 0.83549061 | G30: =SUM(G31:G37) -> 0.83549061
C31: GASTO PERSONAL | D31: =(2000+85+22*36.06+20+150)*'CALCULADORA COSTES'!B16 -> 3048.32 | E31: ='H2'!E31 -> 3200.4 | F31: =E31/E5 -> 0.48490909 | G31: =E31/E5 -> 0.48490909
F32: =E32/E5 -> 0 | G32: =E32/E5 -> 0
C33: GASOIL (0,8 €/L) | D33: ='CALCULADORA COSTES'!D12 -> 0.29463 | E33: =+D33*E5 -> 1944.558 | F33: =E33/E5 -> 0.29463 | G33: =E33/E5 -> 0.29463
C34: AUTOPISTA | E34: ='CALCULADORA COSTES'!F24*'CALCULADORA COSTES'!F25 -> 0 | F34: =E34/E5 -> 0 | G34: =E34/E5 -> 0
C35: NEUMÁTICOS TRACT.(0,0105€/km) | D35: 0.0102 | E35: =+D35*E5*2 -> 134.64 | F35: =E35/E5 -> 0.0204 | G35: =E35/E5 -> 0.0204
C36: NEUMÁTICOS PLAT. (0,0105€/km) | D36: 0.0102 | E36: =+D36*E5*2 -> 134.64 | F36: =E36/E5 -> 0.0204 | G36: =E36/E5 -> 0.0204
C37: OTROS GASTOS | E37: 100 | F37: =E37/E5 -> 0.015151515 | G37: =E37/E5 -> 0.015151515
C40: COSTE TOTAL | E40: =E30+E6 -> 12361.238 | F40: 1 | G40: =SUM(G30+G6) -> 1.8729148
F41: 0 | G41: 0
C42: Planificación Flota | E42: 275 | F42: =E42/E5 -> 0.041666667 | G42: =E42/E5 -> 0.041666667
C43: margen | D43: 0.04 | E43: =+E40*0.04 -> 494.44952 | F43: =E43/E5 -> 0.074916594 | G43: =E43/E5 -> 0.074916594
...

Sheet DUOTRAILER BIOMETANO
E2: € | F2: % | G2: €/KM
C3: KMS DIARIOS
C4: KMS ANUALES
C5: KMS mensuales | E5: ='CALCULADORA COSTES'!B14*'CALCULADORA COSTES'!B15 -> 6600
C6: GASTOS FIJOS | E6: =SUM(E7:E29) -> 5247 | F6: =E6/E$5 -> 0.795 | G6: =E6/E$5 -> 0.795
C7: Cuota TRACTORA | E7: ='CALCULADORA COSTES'!E10 -> 2400 | F7: =E7/E$5 -> 0.36363636 | G7: =E7/E$5 -> 0.36363636
C8: Seguro tract. ( a 3os + Propios+seguro mercancias) | E8: 300 | F8: =E8/E$5 -> 0.045454545 | G8: =E8/E$5 -> 0.045454545
C9: Impto circulación Tract. | E9: 18 | F9: =E9/E$5 -> 0.0027272727 | G9: =E9/E$5 -> 0.0027272727
C10: Mantenimiento Tract. | E10: 400 | F10: =E10/E$5 -> 0.060606061 | G10: =E10/E$5 -> 0.060606061
C11: Reparación Tract.+ Equipo | E11: 100 | F11: =E11/E$5 -> 0.015151515 | G11: =E11/E$5 -> 0.015151515
C12: Equipo Tract. | E12: 50 | F12: =E12/E$5 -> 0.0075757576 | G12: =E12/E$5 -> 0.0075757576
C13: Siniestro Tract. | E13: 150 | F13: =E13/E$5 -> 0.022727273 | G13: =E13/E$5 -> 0.022727273
